Mod_python error: "PythonHandler mod_python.publisher"

Traceback (most recent call last):

  File "/usr/local/lib64/python2.7/site-packages/mod_python/apache.py", line 398, in HandlerDispatch
    result = obj(req)

  File "/usr/local/lib64/python2.7/site-packages/mod_python/publisher.py", line 213, in handler
    module = page_cache[req]

  File "/usr/local/lib64/python2.7/site-packages/mod_python/cache.py", line 89, in __getitem__
    return self._checkitem(name)[2]

  File "/usr/local/lib64/python2.7/site-packages/mod_python/cache.py", line 131, in _checkitem
    value = self.build(key, name, opened, entry)

  File "/usr/local/lib64/python2.7/site-packages/mod_python/publisher.py", line 86, in build
    return ModuleCache.build(self, key, req, opened, entry)

  File "/usr/local/lib64/python2.7/site-packages/mod_python/cache.py", line 380, in build
    exec(opened_as_str, module.__dict__)

  File "<string>", line 4, in <module>

  File "/usr/local/lib/python2.7/site-packages/quandl/__init__.py", line 7, in <module>
    from .model.database import Database

  File "/usr/local/lib/python2.7/site-packages/quandl/model/database.py", line 11, in <module>
    from quandl.connection import Connection

  File "/usr/local/lib/python2.7/site-packages/quandl/connection.py", line 3, in <module>
    import requests

  File "/usr/local/lib/python2.7/site-packages/requests/__init__.py", line 52, in <module>
    from .packages.urllib3.contrib import pyopenssl

  File "/usr/local/lib/python2.7/site-packages/requests/packages/urllib3/contrib/pyopenssl.py", line 47, in <module>
    import OpenSSL.SSL

  File "/usr/local/lib/python2.7/site-packages/OpenSSL/__init__.py", line 8, in <module>
    from OpenSSL import rand, crypto, SSL

  File "/usr/local/lib/python2.7/site-packages/OpenSSL/rand.py", line 12, in <module>
    from OpenSSL._util import (

  File "/usr/local/lib/python2.7/site-packages/OpenSSL/_util.py", line 6, in <module>
    from cryptography.hazmat.bindings.openssl.binding import Binding

  File "/usr/local/lib64/python2.7/site-packages/cryptography/hazmat/bindings/openssl/binding.py", line 207, in <module>
    Binding.init_static_locks()

  File "/usr/local/lib64/python2.7/site-packages/cryptography/hazmat/bindings/openssl/binding.py", line 178, in init_static_locks
    cls._ensure_ffi_initialized()

  File "/usr/local/lib64/python2.7/site-packages/cryptography/hazmat/bindings/openssl/binding.py", line 173, in _ensure_ffi_initialized
    cls._register_osrandom_engine()

  File "/usr/local/lib64/python2.7/site-packages/cryptography/hazmat/bindings/openssl/binding.py", line 138, in _register_osrandom_engine
    _openssl_assert(cls.lib, cls.lib.ERR_peek_error() == 0)

  File "/usr/local/lib64/python2.7/site-packages/cryptography/hazmat/bindings/openssl/binding.py", line 62, in _openssl_assert
    errors_with_text

InternalError: Unknown OpenSSL error. This error is commonly encountered when another library is not cleaning up the OpenSSL error stack. If you are using cryptography with another library that uses OpenSSL try disabling it before reporting a bug. Otherwise please file an issue at https://github.com/pyca/cryptography/issues with information on how to reproduce this. ([_OpenSSLErrorWithText(code=151441516L, lib=9, func=109, reason=108, reason_text='error:0906D06C:PEM routines:PEM_read_bio:no start line'), _OpenSSLErrorWithText(code=151441516L, lib=9, func=109, reason=108, reason_text='error:0906D06C:PEM routines:PEM_read_bio:no start line')])
